<mujoco model="robot">
    <default >
        <geom conaffinity="0" condim="3" density="1.0" friction="1 0.5 0.5" margin="0.01" />
        <default class="leg">
            <joint type="hinge" range="-90 90" armature="1" damping="1" limited="true" frictionloss="10"/>
            <motor ctrlrange="-1 1" gear="100" forcerange="-100 100"/>
        </default>
        <default class="wheel">
            <joint type="hinge" armature="1" damping=".3" limited="false" frictionloss="0"/>
            <motor ctrlrange="-1 1" gear="100" forcerange="-150 150"/>
        </default>
    </default>
    <worldbody>
        <light directional="true" pos="-0.5 0.5 3" dir="0 0 -1" />
        <geom conaffinity="1" name="floor" pos="0 0 0" size="1 1 1" type="plane" rgba="1 0.83 0.61 0.5"/>
        <!-- 构建主体 -->
        <body name="torso" pos="0 0 0.5">
            <joint armature="0" damping="0" limited="false" margin="0.01" name="root" pos="0 0 0" type="free"/>
            <geom name="torso_geom" pos="0 0 0" type="box" size="1.6 0.4 0.4" />
            <!-- 构建主体肌肉节点 -->
            <site name="lf1_1" pos="1.2 0.4 0.4"/>
            <site name="lf1_2" pos="0.8 0.4 0.0"/>
            <site name="lf1_3" pos="1.2 0.4 -0.4"/>
            <site name="lf1_4" pos="1.6 0.4 0.0"/>

            <site name="rf1_1" pos="1.2 -0.4 0.4"/>
            <site name="rf1_2" pos="0.8 -0.4 0.0"/>
            <site name="rf1_3" pos="1.2 -0.4 -0.4"/>
            <site name="rf1_4" pos="1.6 -0.4 0.0"/>

            <site name="lb1_1" pos="-1.2 0.4 0.4"/>
            <site name="lb1_2" pos="-1.6 0.4 0.0"/>
            <site name="lb1_3" pos="-1.2 0.4 -0.4"/>
            <site name="lb1_4" pos="-0.8 0.4 0.0"/>

            <site name="rb1_1" pos="-1.2 -0.4 0.4"/>
            <site name="rb1_2" pos="-1.6 -0.4 0.0"/>
            <site name="rb1_3" pos="-1.2 -0.4 -0.4"/>
            <site name="rb1_4" pos="-0.8 -0.4 0.0"/>
            <!-- 构建左前1腿 -->
            <body name="lf_leg1" pos="1.2 0.9 0">
                <geom name="lf_leg1_geom" pos="0 0 0" fromto="0 -0.5 0 0 0.5 0" size="0.2" type="capsule"/>
                <joint axis="1 0 0" name="lf_leg1_Joint_x" pos="0 -0.5 0" class="leg"/>
                <joint axis="0 0 1" name="lf_leg1_Joint_z" pos="0 -0.5 0" class="leg"/>
                <!-- 构建左前1腿肌肉节点 -->
                <site name="lf1_1e" pos="0.0 0.0 0.2"/>
                <site name="lf1_2e" pos="-0.2 0.0 0.0"/>
                <site name="lf1_3e" pos="0.0 0.0 -0.2"/>
                <site name="lf1_4e" pos="0.2 0.0 0.0"/>
                <site name="lf2_1" pos="0.0 0.0 0.2"/>
                <site name="lf2_2" pos="-0.2 0.0 0.0"/>
                <site name="lf2_3" pos="0.0 0.0 -0.2"/>
                <site name="lf2_4" pos="0.2 0.0 0.0"/>
                <!-- 构建左前2腿 -->
                <body name="lf_leg2" pos="0 1 0">
                    <geom name="lf_leg2_geom" pos="0 0 0" fromto="0 -0.5 0 0 0.5 0" size="0.2" type="capsule"/>
                    <joint axis="1 0 0" name="lf_leg2_Joint_x" pos="0 -0.5 0" class="leg"/>
                    <joint axis="0 0 1" name="lf_leg2_Joint_z" pos="0 -0.5 0" class="leg"/>
                    <!-- 构建左前2腿肌肉节点 -->
                    <site name="lf2_1e" pos="0.0 0.0 0.2"/>
                    <site name="lf2_2e" pos="-0.2 0.0 0.0"/>
                    <site name="lf2_3e" pos="0.0 0.0 -0.2"/>
                    <site name="lf2_4e" pos="0.2 0.0 0.0"/>
                    <site name="lf3_1" pos="0.0 0.0 0.2"/>
                    <site name="lf3_2" pos="-0.2 0.0 0.0"/>
                    <site name="lf3_3" pos="0.0 0.0 -0.2"/>
                    <site name="lf3_4" pos="0.2 0.0 0.0"/>
                    <!-- 构建左前3腿 -->
                    <body name="lf_leg3" pos="0 0.75 0">
                        <geom name="lf_leg3_geom" pos="0 0 0" fromto="0 -0.25 0 0 0.25 0" size="0.2" type="box"/>
                        <joint axis="1 0 0" name="lf_leg3_Joint_x" pos="0 -0.25 0" class="leg"/>
                        <joint axis="0 0 1" name="lf_leg3_Joint_z" pos="0 -0.25 0" class="leg"/>
                        <!-- 构建左前3腿肌肉节点 -->
                        <site name="lf3_1e" pos="0.0 0.0 0.2"/>
                        <site name="lf3_2e" pos="-0.2 0.0 0.0"/>
                        <site name="lf3_3e" pos="0.0 0.0 -0.2"/>
                        <site name="lf3_4e" pos="0.2 0.0 0.0"/>
                        <body name ="lf_motor" pos="0 0.3 0">
                            <geom name ="lf_motor_geom" pos="0 0 0" type="cylinder" size="0.8" fromto="0 -0.05 0 0 0.05 0"/>
                            <joint axis="0 1 0" name="lf_motor_y" pos="0 -0.1 0" class="wheel"/>
                        </body>
                    </body>
                </body>
            </body>
            <!-- 构建右前1腿 -->
            <body name="rf_leg1" pos="1.2 -0.9 0">
                <geom name="rf_leg1_geom" pos="0 0 0" fromto="0 -0.5 0 0 0.5 0" size="0.2" type="capsule"/>
                <joint axis="1 0 0" name="rf_leg1_Joint_x" pos="0 0.5 0" class="leg"/>
                <joint axis="0 0 1" name="rf_leg1_Joint_z" pos="0 0.5 0" class="leg"/>

                <site name="rf1_1e" pos="0.0 0.0 0.2"/>
                <site name="rf1_2e" pos="-0.2 0.0 0.0"/>
                <site name="rf1_3e" pos="0.0 0.0 -0.2"/>
                <site name="rf1_4e" pos="0.2 0.0 0.0"/>
                <site name="rf2_1" pos="0.0 0.0 0.2"/>
                <site name="rf2_2" pos="-0.2 0.0 0.0"/>
                <site name="rf2_3" pos="0.0 0.0 -0.2"/>
                <site name="rf2_4" pos="0.2 0.0 0.0"/>
                <!-- 构建右前2腿 -->
                <body name="rf_leg2" pos="0 -1 0">
                    <geom name="rf_leg2_geom" pos="0 0 0" fromto="0 -0.5 0 0 0.5 0" size="0.2" type="capsule"/>
                    <joint axis="1 0 0" name="rf_leg2_Joint_x" pos="0 0.5 0" class="leg"/>
                    <joint axis="0 0 1" name="rf_leg2_Joint_z" pos="0 0.5 0" class="leg"/>
                    <site name="rf2_1e" pos="0.0 0.0 0.2"/>
                    <site name="rf2_2e" pos="-0.2 0.0 0.0"/>
                    <site name="rf2_3e" pos="0.0 0.0 -0.2"/>
                    <site name="rf2_4e" pos="0.2 0.0 0.0"/>
                    <site name="rf3_1" pos="0.0 0.0 0.2"/>
                    <site name="rf3_2" pos="-0.2 0.0 0.0"/>
                    <site name="rf3_3" pos="0.0 0.0 -0.2"/>
                    <site name="rf3_4" pos="0.2 0.0 0.0"/>
                    <!-- 构建右前3腿 -->
                    <body name="rf_leg3" pos="0 -0.75 0">
                        <geom name="rf_leg3_geom" pos="0 0 0" fromto="0 -0.25 0 0 0.25 0" size="0.2" type="box"/>
                        <joint axis="1 0 0" name="rf_leg3_Joint_x" pos="0 0.25 0" class="leg"/>
                        <joint axis="0 0 1" name="rf_leg3_Joint_z" pos="0 0.25 0" class="leg"/>
                        <site name="rf3_1e" pos="0.0 0.0 0.2"/>
                        <site name="rf3_2e" pos="-0.2 0.0 0.0"/>
                        <site name="rf3_3e" pos="0.0 0.0 -0.2"/>
                        <site name="rf3_4e" pos="0.2 0.0 0.0"/>
                        <body name ="rf_motor" pos="0 -0.3 0">
                            <geom name ="rf_motor_geom" pos="0 0 0" type="cylinder" size="0.8" fromto="0 -0.05 0 0 0.05 0"/>
                            <joint axis="0 1 0" name="rf_motor_y" pos="0 0.1 0" class="wheel"/>
                        </body>
                    </body>
                </body>
            </body>
            <!-- 构建左后1腿 -->
            <body name="lb_leg1" pos="-1.2 0.9 0">
                <geom name="lb_leg1_geom" pos="0 0 0" fromto="0 -0.5 0 0 0.5 0" size="0.2" type="capsule"/>
                <joint axis="1 0 0" name="lb_leg1_Joint_x" pos="0 -0.5 0" class="leg"/>
                <joint axis="0 0 1" name="lb_leg1_Joint_z" pos="0 -0.5 0" class="leg"/>
                <site name="lb1_1e" pos="0.0 0.0 0.2"/>
                <site name="lb1_2e" pos="-0.2 0.0 0.0"/>
                <site name="lb1_3e" pos="0.0 0.0 -0.2"/>
                <site name="lb1_4e" pos="0.2 0.0 0.0"/>
                <site name="lb2_1" pos="0.0 0.0 0.2"/>
                <site name="lb2_2" pos="-0.2 0.0 0.0"/>
                <site name="lb2_3" pos="0.0 0.0 -0.2"/>
                <site name="lb2_4" pos="0.2 0.0 0.0"/>
                <!-- 构建左后2腿 -->
                <body name="lb_leg2" pos="0 1 0">
                    <geom name="lb_leg2_geom" pos="0 0 0" fromto="0 -0.5 0 0 0.5 0" size="0.2" type="capsule"/>
                    <joint axis="1 0 0" name="lb_leg2_Joint_x" pos="0 -0.5 0" class="leg"/>
                    <joint axis="0 0 1" name="lb_leg2_Joint_z" pos="0 -0.5 0" class="leg"/>
                    <site name="lb2_1e" pos="0.0 0.0 0.2"/>
                    <site name="lb2_2e" pos="-0.2 0.0 0.0"/>
                    <site name="lb2_3e" pos="0.0 0.0 -0.2"/>
                    <site name="lb2_4e" pos="0.2 0.0 0.0"/>
                    <site name="lb3_1" pos="0.0 0.0 0.2"/>
                    <site name="lb3_2" pos="-0.2 0.0 0.0"/>
                    <site name="lb3_3" pos="0.0 0.0 -0.2"/>
                    <site name="lb3_4" pos="0.2 0.0 0.0"/>
                    <!-- 构建左后3腿 -->
                    <body name="lb_leg3" pos="0 0.75 0">
                        <geom name="lb_leg3_geom" pos="0 0 0" fromto="0 -0.25 0 0 0.25 0" size="0.2" type="box"/>
                        <joint axis="1 0 0" name="lb_leg3_Joint_x" pos="0 -0.25 0" class="leg"/>
                        <joint axis="0 0 1" name="lb_leg3_Joint_z" pos="0 -0.25 0" class="leg"/>
                        <site name="lb3_1e" pos="0.0 0.0 0.2"/>
                        <site name="lb3_2e" pos="-0.2 0.0 0.0"/>
                        <site name="lb3_3e" pos="0.0 0.0 -0.2"/>
                        <site name="lb3_4e" pos="0.2 0.0 0.0"/>
                        <body name ="lb_motor" pos="0 0.3 0">
                            <geom name ="lb_motor_geom" pos="0 0 0" type="cylinder" size="0.8" fromto="0 -0.05 0 0 0.05 0"/>
                            <joint axis="0 1 0" name="lb_motor_y" pos="0 -0.1 0" class="wheel"/>
                        </body>
                    </body>
                </body>
            </body>
            <!-- 构建右后1腿 -->
            <body name="rb_leg1" pos="-1.2 -0.9 0">
                <geom name="rb_leg1_geom" pos="0 0 0" fromto="0 -0.5 0 0 0.5 0" size="0.2" type="capsule"/>
                <joint axis="1 0 0" name="rb_leg1_Joint_x" pos="0 0.5 0" class="leg"/>
                <joint axis="0 0 1" name="rb_leg1_Joint_z" pos="0 0.5 0" class="leg"/>
               
                <site name="rb1_1e" pos="0.0 0.0 0.2"/>
                <site name="rb1_2e" pos="-0.2 0.0 0.0"/>
                <site name="rb1_3e" pos="0.0 0.0 -0.2"/>
                <site name="rb1_4e" pos="0.2 0.0 0.0"/>
                <site name="rb2_1" pos="0.0 0.0 0.2"/>
                <site name="rb2_2" pos="-0.2 0.0 0.0"/>
                <site name="rb2_3" pos="0.0 0.0 -0.2"/>
                <site name="rb2_4" pos="0.2 0.0 0.0"/>
                <!-- 构建右后2腿 -->
                <body name="rb_leg2" pos="0 -1 0">
                    <geom name="rb_leg2_geom" pos="0 0 0" fromto="0 -0.5 0 0 0.5 0" size="0.2" type="capsule"/>
                    <joint axis="1 0 0" name="rb_leg2_Joint_x" pos="0 0.5 0" class="leg"/>
                    <joint axis="0 0 1" name="rb_leg2_Joint_z" pos="0 0.5 0" class="leg"/>
                    <site name="rb2_1e" pos="0.0 0.0 0.2"/>
                    <site name="rb2_2e" pos="-0.2 0.0 0.0"/>
                    <site name="rb2_3e" pos="0.0 0.0 -0.2"/>
                    <site name="rb2_4e" pos="0.2 0.0 0.0"/>
                    <site name="rb3_1" pos="0.0 0.0 0.2"/>
                    <site name="rb3_2" pos="-0.2 0.0 0.0"/>
                    <site name="rb3_3" pos="0.0 0.0 -0.2"/>
                    <site name="rb3_4" pos="0.2 0.0 0.0"/>
                    <!-- 构建右后3腿 -->
                    <body name="rb_leg3" pos="0 -0.75 0">
                        <geom name="rb_leg3_geom" pos="0 0 0" fromto="0 -0.25 0 0 0.25 0" size="0.2" type="box"/>
                        <joint axis="1 0 0" name="rb_leg3_Joint_x" pos="0 0.25 0" class="leg"/>
                        <joint axis="0 0 1" name="rb_leg3_Joint_z" pos="0 0.25 0" class="leg"/>
                        <site name="rb3_1e" pos="0.0 0.0 0.2"/>
                        <site name="rb3_2e" pos="-0.2 0.0 0.0"/>
                        <site name="rb3_3e" pos="0.0 0.0 -0.2"/>
                        <site name="rb3_4e" pos="0.2 0.0 0.0"/>
                        <body name ="rb_motor" pos="0 -0.3 0">
                            <geom name ="rb_motor_geom" pos="0 0 0" type="cylinder" size="0.8" fromto="0 -0.05 0 0 0.05 0"/>
                            <joint axis="0 1 0" name="rb_motor_y" pos="0 0.1 0" class="wheel"/>
                        </body>
                    </body>
                </body>
            </body>

        </body>
    </worldbody> 
    <!-- 肌肉 -->
    <tendon>
        <!-- 构建左前1腿肌肉组 -->
        <spatial name="lf1_1" width=".02" rgba=".95 .3 .3 1">
            <site site="lf1_1"/>
            <site site="lf1_1e"/>
        </spatial>
        <spatial name="lf1_2" width=".02" rgba=".95 .3 .3 1">
            <site site="lf1_2"/>
            <site site="lf1_2e"/>
        </spatial>
        <spatial name="lf1_3" width=".02" rgba=".95 .3 .3 1">
            <site site="lf1_3"/>
            <site site="lf1_3e"/>
        </spatial>
        <spatial name="lf1_4" width=".02" rgba=".95 .3 .3 1">
            <site site="lf1_4"/>
            <site site="lf1_4e"/>
        </spatial>
        <!-- 构建左前2腿肌肉组 -->
        <spatial name="lf2_1" width=".02" rgba=".95 .3 .3 1">
            <site site="lf2_1"/>
            <site site="lf2_1e"/>
        </spatial>
        <spatial name="lf2_2" width=".02" rgba=".95 .3 .3 1">
            <site site="lf2_2"/>
            <site site="lf2_2e"/>
        </spatial>
        <spatial name="lf2_3" width=".02" rgba=".95 .3 .3 1">
            <site site="lf2_3"/>
            <site site="lf2_3e"/>
        </spatial>
        <spatial name="lf2_4" width=".02" rgba=".95 .3 .3 1">
            <site site="lf2_4"/>
            <site site="lf2_4e"/>
        </spatial>
        <!-- 构建左前3腿肌肉组 -->
        <spatial name="lf3_1" width=".02" rgba=".95 .3 .3 1">
            <site site="lf3_1"/>
            <site site="lf3_1e"/>
        </spatial>
        <spatial name="lf3_2" width=".02" rgba=".95 .3 .3 1">
            <site site="lf3_2"/>
            <site site="lf3_2e"/>
        </spatial>
        <spatial name="lf3_3" width=".02" rgba=".95 .3 .3 1">
            <site site="lf3_3"/>
            <site site="lf3_3e"/>
        </spatial>
        <spatial name="lf3_4" width=".02" rgba=".95 .3 .3 1">
            <site site="lf3_4"/>
            <site site="lf3_4e"/>
        </spatial>

        <!-- 构建右前1腿肌肉组 -->
        <spatial name="rf1_1" width=".02" rgba=".95 .3 .3 1">
            <site site="rf1_1"/>
            <site site="rf1_1e"/>
        </spatial>
        <spatial name="rf1_2" width=".02" rgba=".95 .3 .3 1">
            <site site="rf1_2"/>
            <site site="rf1_2e"/>
        </spatial>
        <spatial name="rf1_3" width=".02" rgba=".95 .3 .3 1">
            <site site="rf1_3"/>
            <site site="rf1_3e"/>
        </spatial>
        <spatial name="rf1_4" width=".02" rgba=".95 .3 .3 1">
            <site site="rf1_4"/>
            <site site="rf1_4e"/>
        </spatial>
        <!-- 构建右前2腿肌肉组 -->
        <spatial name="rf2_1" width=".02" rgba=".95 .3 .3 1">
            <site site="rf2_1"/>
            <site site="rf2_1e"/>
        </spatial>
        <spatial name="rf2_2" width=".02" rgba=".95 .3 .3 1">
            <site site="rf2_2"/>
            <site site="rf2_2e"/>
        </spatial>
        <spatial name="rf2_3" width=".02" rgba=".95 .3 .3 1">
            <site site="rf2_3"/>
            <site site="rf2_3e"/>
        </spatial>
        <spatial name="rf2_4" width=".02" rgba=".95 .3 .3 1">
            <site site="rf2_4"/>
            <site site="rf2_4e"/>
        </spatial>
        <!-- 构建右前3腿肌肉组 -->
        <spatial name="rf3_1" width=".02" rgba=".95 .3 .3 1">
            <site site="rf3_1"/>
            <site site="rf3_1e"/>
        </spatial>
        <spatial name="rf3_2" width=".02" rgba=".95 .3 .3 1">
            <site site="rf3_2"/>
            <site site="rf3_2e"/>
        </spatial>
        <spatial name="rf3_3" width=".02" rgba=".95 .3 .3 1">
            <site site="rf3_3"/>
            <site site="rf3_3e"/>
        </spatial>
        <spatial name="rf3_4" width=".02" rgba=".95 .3 .3 1">
            <site site="rf3_4"/>
            <site site="rf3_4e"/>
        </spatial>

        <!-- 构建左后1腿肌肉组 -->
        <spatial name="lb1_1" width=".02" rgba=".95 .3 .3 1">
            <site site="lb1_1"/>
            <site site="lb1_1e"/>
        </spatial>
        <spatial name="lb1_2" width=".02" rgba=".95 .3 .3 1">
            <site site="lb1_2"/>
            <site site="lb1_2e"/>
        </spatial>
        <spatial name="lb1_3" width=".02" rgba=".95 .3 .3 1">
            <site site="lb1_3"/>
            <site site="lb1_3e"/>
        </spatial>
        <spatial name="lb1_4" width=".02" rgba=".95 .3 .3 1">
            <site site="lb1_4"/>
            <site site="lb1_4e"/>
        </spatial>
        <!-- 构建左后2腿肌肉组 -->
        <spatial name="lb2_1" width=".02" rgba=".95 .3 .3 1">
            <site site="lb2_1"/>
            <site site="lb2_1e"/>
        </spatial>
        <spatial name="lb2_2" width=".02" rgba=".95 .3 .3 1">
            <site site="lb2_2"/>
            <site site="lb2_2e"/>
        </spatial>
        <spatial name="lb2_3" width=".02" rgba=".95 .3 .3 1">
            <site site="lb2_3"/>
            <site site="lb2_3e"/>
        </spatial>
        <spatial name="lb2_4" width=".02" rgba=".95 .3 .3 1">
            <site site="lb2_4"/>
            <site site="lb2_4e"/>
        </spatial>
        <!-- 构建左后3腿肌肉组 -->
        <spatial name="lb3_1" width=".02" rgba=".95 .3 .3 1">
            <site site="lb3_1"/>
            <site site="lb3_1e"/>
        </spatial>
        <spatial name="lb3_2" width=".02" rgba=".95 .3 .3 1">
            <site site="lb3_2"/>
            <site site="lb3_2e"/>
        </spatial>
        <spatial name="lb3_3" width=".02" rgba=".95 .3 .3 1">
            <site site="lb3_3"/>
            <site site="lb3_3e"/>
        </spatial>
        <spatial name="lb3_4" width=".02" rgba=".95 .3 .3 1">
            <site site="lb3_4"/>
            <site site="lb3_4e"/>
        </spatial>

        <!-- 构建右后1腿肌肉组 -->
        <spatial name="rb1_1" width=".02" rgba=".95 .3 .3 1">
            <site site="rb1_1"/>
            <site site="rb1_1e"/>
        </spatial>
        <spatial name="rb1_2" width=".02" rgba=".95 .3 .3 1">
            <site site="rb1_2"/>
            <site site="rb1_2e"/>
        </spatial>
        <spatial name="rb1_3" width=".02" rgba=".95 .3 .3 1">
            <site site="rb1_3"/>
            <site site="rb1_3e"/>
        </spatial>
        <spatial name="rb1_4" width=".02" rgba=".95 .3 .3 1">
            <site site="rb1_4"/>
            <site site="rb1_4e"/>
        </spatial>
        <!-- 构建右后2腿肌肉组 -->
        <spatial name="rb2_1" width=".02" rgba=".95 .3 .3 1">
            <site site="rb2_1"/>
            <site site="rb2_1e"/>
        </spatial>
        <spatial name="rb2_2" width=".02" rgba=".95 .3 .3 1">
            <site site="rb2_2"/>
            <site site="rb2_2e"/>
        </spatial>
        <spatial name="rb2_3" width=".02" rgba=".95 .3 .3 1">
            <site site="rb2_3"/>
            <site site="rb2_3e"/>
        </spatial>
        <spatial name="rb2_4" width=".02" rgba=".95 .3 .3 1">
            <site site="rb2_4"/>
            <site site="rb2_4e"/>
        </spatial>
        <!-- 构建右后2腿肌肉组 -->
        <spatial name="rb3_1" width=".02" rgba=".95 .3 .3 1">
            <site site="rb3_1"/>
            <site site="rb3_1e"/>
        </spatial>
        <spatial name="rb3_2" width=".02" rgba=".95 .3 .3 1">
            <site site="rb3_2"/>
            <site site="rb3_2e"/>
        </spatial>
        <spatial name="rb3_3" width=".02" rgba=".95 .3 .3 1">
            <site site="rb3_3"/>
            <site site="rb3_3e"/>
        </spatial>
        <spatial name="rb3_4" width=".02" rgba=".95 .3 .3 1">
            <site site="rb3_4"/>
            <site site="rb3_4e"/>
        </spatial>
    </tendon>
    <actuator>
        <!-- 构建左前肌肉组驱动 -->
        <muscle name="lfm1_1" tendon="lf1_1"/>
        <muscle name="lfm1_2" tendon="lf1_2"/>
        <muscle name="lfm1_3" tendon="lf1_3"/>
        <muscle name="lfm1_4" tendon="lf1_4"/>

        <muscle name="lfm2_1" tendon="lf2_1"/>
        <muscle name="lfm2_2" tendon="lf2_2"/>
        <muscle name="lfm2_3" tendon="lf2_3"/>
        <muscle name="lfm2_4" tendon="lf2_4"/>

        <muscle name="lfm3_1" tendon="lf3_1"/>
        <muscle name="lfm3_2" tendon="lf3_2"/>
        <muscle name="lfm3_3" tendon="lf3_3"/>
        <muscle name="lfm3_4" tendon="lf3_4"/>
        <!-- 构建左后肌肉组驱动 -->
        <muscle name="lbm1_1" tendon="lb1_1"/>
        <muscle name="lbm1_2" tendon="lb1_2"/>
        <muscle name="lbm1_3" tendon="lb1_3"/>
        <muscle name="lbm1_4" tendon="lb1_4"/>

        <muscle name="lbm2_1" tendon="lb2_1"/>
        <muscle name="lbm2_2" tendon="lb2_2"/>
        <muscle name="lbm2_3" tendon="lb2_3"/>
        <muscle name="lbm2_4" tendon="lb2_4"/>

        <muscle name="lbm3_1" tendon="lb3_1"/>
        <muscle name="lbm3_2" tendon="lb3_2"/>
        <muscle name="lbm3_3" tendon="lb3_3"/>
        <muscle name="lbm3_4" tendon="lb3_4"/>
        <!-- 构建右前肌肉组驱动 -->
        <muscle name="rfm1_1" tendon="rf1_1"/>
        <muscle name="rfm1_2" tendon="rf1_2"/>
        <muscle name="rfm1_3" tendon="rf1_3"/>
        <muscle name="rfm1_4" tendon="rf1_4"/>

        <muscle name="rfm2_1" tendon="rf2_1"/>
        <muscle name="rfm2_2" tendon="rf2_2"/>
        <muscle name="rfm2_3" tendon="rf2_3"/>
        <muscle name="rfm2_4" tendon="rf2_4"/>

        <muscle name="rfm3_1" tendon="rf3_1"/>
        <muscle name="rfm3_2" tendon="rf3_2"/>
        <muscle name="rfm3_3" tendon="rf3_3"/>
        <muscle name="rfm3_4" tendon="rf3_4"/>
        <!-- 构建右后肌肉组驱动 -->
        <muscle name="rbm1_1" tendon="rb1_1"/>
        <muscle name="rbm1_2" tendon="rb1_2"/>
        <muscle name="rbm1_3" tendon="rb1_3"/>
        <muscle name="rbm1_4" tendon="rb1_4"/>

        <muscle name="rbm2_1" tendon="rb2_1"/>
        <muscle name="rbm2_2" tendon="rb2_2"/>
        <muscle name="rbm2_3" tendon="rb2_3"/>
        <muscle name="rbm2_4" tendon="rb2_4"/>

        <muscle name="rbm3_1" tendon="rb3_1"/>
        <muscle name="rbm3_2" tendon="rb3_2"/>
        <muscle name="rbm3_3" tendon="rb3_3"/>
        <muscle name="rbm3_4" tendon="rb3_4"/>
        
        <motor name="lf_motor" joint="lf_motor_y" class="wheel"/>
        <motor name="rf_motor" joint="rf_motor_y" class="wheel"/>
        <motor name="lb_motor" joint="lb_motor_y" class="wheel"/>
        <motor name="rb_motor" joint="rb_motor_y" class="wheel"/>
    </actuator>
</mujoco>